Workbook

Sheet Read_First
A2: UEQ+ Data Analysis Tool Author: Dr. Martin Schrepp
A3: The goal of this tool is to make the analysis of UEQ+ (Modular extension of the User Experience Questionnaire) data as easy as possible for you. The UEQ+ is a set of scales that can combined to form a concrete UX questionnaire. Thus, it is possible to create a questionnaire that fits exactly to the needs of the evaluated product. Each scale consists of 4 items that measure the impression of subject towards the UX aspect represented by the scale and a single item that measures the relevance or importance of the scale for the subject. You simply enter the data obtained from your respondents into the Data_Items (data for the 4 items for each scale) and Data_Importance (data for the importance ratings) worksheet. The tool then automatically calculates all statistics necessary to interpret the results. Simply copy them to your word processor or presentation tool. The instructions, scale names and items in this tool are in English. To make the interpretation of the results easier and to have the results in your language you can change the texts in the worksheet Texts. This will impact all scale names and items.
A4: The data analysis tool contains the following worksheets: Data_Items: Observed data for the items in each scale. Data_Importance: Observed data concerning the importance ratings of the scales. Means: Means, standard deviation and confidence intervalls for the scales, importance ratings and single items. Consistency: Cronbach Alpha value and correlation of all items in each scale. KPI: An overall KPI calculated from the items and importance ratings. Texts: Constains the texts for the scale names and items.

Sheet Data_Items
A1: Please enter the data for the UEQ+ Items here! The data analysis tool is delivered with some example data in this work sheet. Simply delete them before you enter your data here. The UEQ+ is a modular tool to create a concrete questionnaire, thus the researcher can select the scales and their order. Therefore, this choice must be entered to the data analysis tool first. First step: Choose the scales you selected in row 3 from left to right in the order you use them in the questionnaire! Use the dropdown which shows all available scales. Second step: The data analysis tool allows to do an analysis for up to 10 selected scales. However, in most applications less than 10 scales will be used. Set the remaining columns for the scales to the value "Skala wählen". Third step: Now enter the data from your questionnaire in the rows (starting with row 4). Use the values 1 (if the alternative on the extreme left is marked) to 7 (if the alternative on the extreme right is marked). Leave the cell empty if the person has not answered the item. Please do not enter a special caracter in such cases, since this would cause errors in the calculations. You can enter data for a maximum of 1000 participants. If you need more, you have to adjust the fomulas in the Excel. Make sure that missing values are represented by empty cells and not by a " " in a cell! Otherwise some errors will show up!
A2: Enter the observed item ratings here | AR2: Scale Means per Participant (Calculated, do not modify the cells below)
A3: Intuitive Use | E3: Trustworthiness of Content | I3: Response Behavior | M3: Response Quality | Q3: Clarity | U3: Risk Handling | Y3: Choose Scale | AC3: Choose Scale | AG3: Choose Scale | AK3: Choose Scale | AR3: =A3 -> Intuitive Use | AS3: =E3 -> Trustworthiness of Content | AT3: =I3 -> Response Behavior | AU3: =M3 -> Response Quality | AV3: =Q3 -> Clarity | AW3: =U3 -> Risk Handling | AX3: =Y3 -> Choose Scale | AY3: =AC3 -> Choose Scale | AZ3: =AG3 -> Choose Scale | BA3: =AK3 -> Choose Scale
A4: 6 | B4: 5 | C4: 6 | D4: 7 | E4: 3 | F4: 1 | G4: 2 | H4: 2 | I4: 5 | J4: 3 | K4: 3 | L4: 2 | M4: 2 | N4: 1 | O4: 3 | P4: 1 | Q4: 6 | R4: 5 | S4: 6 | T4: 6 | U4: 1 | V4: 2 | W4: 2 | X4: 4 | AR4: =IF(COUNTA(A4:D4)>0,AVERAGE(A4:D4),"") -> 6 | AS4: =IF(COUNTA(E4:H4)>0,AVERAGE(E4:H4),"") -> 2 | AT4: =IF(COUNTA(I4:K4)>0,AVERAGE(I4:K4),"") -> 3.6666667 | AU4: =IF(COUNTA(L4:P4)>0,AVERAGE(L4:P4),"") -> 1.8 | AV4: =IF(COUNTA(Q4:T4)>0,AVERAGE(Q4:T4),"") -> 5.75 | AW4: =IF(COUNTA(U4:X4)>0,AVERAGE(U4:X4),"") -> 2.25 | AX4: =IF(COUNTA(Y4:AB4)>0,AVERAGE(Y4:AB4),"") | AY4: =IF(COUNTA(AC4:AF4)>0,AVERAGE(AC4:AF4),"") | AZ4: =IF(COUNTA(AG4:AJ4)>0,AVERAGE(AG4:AJ4),"") | BA4: =IF(COUNTA(AK4:AN4)>0,AVERAGE(AK4:AN4),"")
A5: 7 | B5: 7 | C5: 7 | D5: 6 | E5: 6 | F5: 4 | G5: 5 | H5: 5 | I5: 5 | J5: 6 | K5: 6 | L5: 6 | M5: 6 | N5: 5 | O5: 5 | P5: 4 | Q5: 7 | R5: 7 | S5: 7 | T5: 7 | U5: 3 | V5: 4 | W5: 6 | X5: 5 | AR5: =IF(COUNTA(A5:D5)>0,AVERAGE(A5:D5),"") -> 6.75 | AS5: =IF(COUNTA(E5:H5)>0,AVERAGE(E5:H5),"") -> 5 | AT5: =IF(COUNTA(I5:K5)>0,AVERAGE(I5:K5),"") -> 5.6666667 | AU5: =IF(COUNTA(L5:P5)>0,AVERAGE(L5:P5),"") -> 5.2 | AV5: =IF(COUNTA(Q5:T5)>0,AVERAGE(Q5:T5),"") -> 7 | AW5: =IF(COUNTA(U5:X5)>0,AVERAGE(U5:X5),"") -> 4.5 | AX5: =IF(COUNTA(Y5:AB5)>0,AVERAGE(Y5:AB5),"") | AY5: =IF(COUNTA(AC5:AF5)>0,AVERAGE(AC5:AF5),"") | AZ5: =IF(COUNTA(AG5:AJ5)>0,AVERAGE(AG5:AJ5),"") | BA5: =IF(COUNTA(AK5:AN5)>0,AVERAGE(AK5:AN5),"")
A6: 7 | B6: 7 | C6: 7 | D6: 7 | E6: 2 | F6: 6 | G6: 2 | H6: 2 | I6: 7 | J6: 7 | K6: 5 | L6: 6 | M6: 2 | N6: 2 | O6: 2 | P6: 2 | Q6: 7 | R6: 7 | S6: 7 | T6: 7 | U6: 6 | V6: 6 | W6: 6 | X6: 3 | AR6: =IF(COUNTA(A6:D6)>0,AVERAGE(A6:D6),"") -> 7 | AS6: =IF(COUNTA(E6:H6)>0,AVERAGE(E6:H6),"") -> 3 | AT6: =IF(COUNTA(I6:K6)>0,AVERAGE(I6:K6),"") -> 6.3333333 | AU6: =IF(COUNTA(L6:P6)>0,AVERAGE(L6:P6),"") -> 2.8 | AV6: =IF(COUNTA(Q6:T6)>0,AVERAGE(Q6:T6),"") -> 7 | AW6: =IF(COUNTA(U6:X6)>0,AVERAGE(U6:X6),"") -> 5.25 | AX6: =IF(COUNTA(Y6:AB6)>0,AVERAGE(Y6:AB6),"") | AY6: =IF(COUNTA(AC6:AF6)>0,AVERAGE(AC6:AF6),"") | AZ6: =IF(COUNTA(AG6:AJ6)>0,AVERAGE(AG6:AJ6),"") | BA6: =IF(COUNTA(AK6:AN6)>0,AVERAGE(AK6:AN6),"")
A7: 6 | B7: 5 | C7: 5 | D7: 4 | E7: 4 | F7: 5 | G7: 4 | H7: 4 | I7: 5 | J7: 5 | K7: 5 | L7: 5 | M7: 5 | N7: 4 | O7: 4 | P7: 5 | Q7: 5 | R7: 5 | S7: 5 | T7: 5 | U7: 4 | V7: 4 | W7: 4 | X7: 5 | AR7: =IF(COUNTA(A7:D7)>0,AVERAGE(A7:D7),"") -> 5 | AS7: =IF(COUNTA(E7:H7)>0,AVERAGE(E7:H7),"") -> 4.25 | AT7: =IF(COUNTA(I7:K7)>0,AVERAGE(I7:K7),"") -> 5 | AU7: =IF(COUNTA(L7:P7)>0,AVERAGE(L7:P7),"") -> 4.6 | AV7: =IF(COUNTA(Q7:T7)>0,AVERAGE(Q7:T7),"") -> 5 | AW7: =IF(COUNTA(U7:X7)>0,AVERAGE(U7:X7),"") -> 4.25 | AX7: =IF(COUNTA(Y7:AB7)>0,AVERAGE(Y7:AB7),"") | AY7: =IF(COUNTA(AC7:AF7)>0,AVERAGE(AC7:AF7),"") | AZ7: =IF(COUNTA(AG7:AJ7)>0,AVERAGE(AG7:AJ7),"") | BA7: =IF(COUNTA(AK7:AN7)>0,AVERAGE(AK7:AN7),"")
A8: 7 | B8: 7 | C8: 7 | D8: 7 | E8: 6 | F8: 6 | G8: 5 | H8: 5 | I8: 7 | J8: 7 | K8: 6 | L8: 6 | M8: 7 | N8: 6 | O8: 6 | P8: 7 | Q8: 7 | R8: 7 | S8: 7 | T8: 7 | U8: 2 | V8: 2 | W8: 2 | X8: 5 | AR8: =IF(COUNTA(A8:D8)>0,AVERAGE(A8:D8),"") -> 7 | AS8: =IF(COUNTA(E8:H8)>0,AVERAGE(E8:H8),"") -> 5.5 | AT8: =IF(COUNTA(I8:K8)>0,AVERAGE(I8:K8),"") -> 6.6666667 | AU8: =IF(COUNTA(L8:P8)>0,AVERAGE(L8:P8),"") -> 6.4 | AV8: =IF(COUNTA(Q8:T8)>0,AVERAGE(Q8:T8),"") -> 7 | AW8: =IF(COUNTA(U8:X8)>0,AVERAGE(U8:X8),"") -> 2.75 | AX8: =IF(COUNTA(Y8:AB8)>0,AVERAGE(Y8:AB8),"") | AY8: =IF(COUNTA(AC8:AF8)>0,AVERAGE(AC8:AF8),"") | AZ8: =IF(COUNTA(AG8:AJ8)>0,AVERAGE(AG8:AJ8),"") | BA8: =IF(COUNTA(AK8:AN8)>0,AVERAGE(AK8:AN8),"")
A9: 7 | B9: 7 | C9: 7 | D9: 7 | E9: 1 | F9: 1 | G9: 1 | H9: 1 | I9: 1 | J9: 1 | K9: 1 | L9: 3 | M9: 1 | N9: 1 | O9: 1 | P9: 1 | Q9: 7 | R9: 7 | S9: 7 | T9: 7 | U9: 3 | V9: 1 | W9: 1 | X9: 1 | AR9: =IF(COUNTA(A9:D9)>0,AVERAGE(A9:D9),"") -> 7 | AS9: =IF(COUNTA(E9:H9)>0,AVERAGE(E9:H9),"") -> 1 | AT9: =IF(COUNTA(I9:K9)>0,AVERAGE(I9:K9),"") -> 1 | AU9: =IF(COUNTA(L9:P9)>0,AVERAGE(L9:P9),"") -> 1.4 | AV9: =IF(COUNTA(Q9:T9)>0,AVERAGE(Q9:T9),"") -> 7 | AW9: =IF(COUNTA(U9:X9)>0,AVERAGE(U9:X9),"") -> 1.5 | AX9: =IF(COUNTA(Y9:AB9)>0,AVERAGE(Y9:AB9),"") | AY9: =IF(COUNTA(AC9:AF9)>0,AVERAGE(AC9:AF9),"") | AZ9: =IF(COUNTA(AG9:AJ9)>0,AVERAGE(AG9:AJ9),"") | BA9: =IF(COUNTA(AK9:AN9)>0,AVERAGE(AK9:AN9),"")
A10: 7 | B10: 7 | C10: 7 | D10: 7 | E10: 6 | F10: 6 | G10: 5 | H10: 6 | I10: 6 | J10: 7 | K10: 7 | L10: 5 | M10: 6 | N10: 7 | O10: 5 | P10: 6 | Q10: 7 | R10: 7 | S10: 7 | T10: 7 | U10: 2 | V10: 1 | W10: 1 | X10: 2 | AR10: =IF(COUNTA(A10:D10)>0,AVERAGE(A10:D10),"") -> 7 | AS10: =IF(COUNTA(E10:H10)>0,AVERAGE(E10:H10),"") -> 5.75 | AT10: =IF(COUNTA(I10:K10)>0,AVERAGE(I10:K10),"") -> 6.6666667 | AU10: =IF(COUNTA(L10:P10)>0,AVERAGE(L10:P10),"") -> 5.8 | AV10: =IF(COUNTA(Q10:T10)>0,AVERAGE(Q10:T10),"") -> 7 | AW10: =IF(COUNTA(U10:X10)>0,AVERAGE(U10:X10),"") -> 1.5 | AX10: =IF(COUNTA(Y10:AB10)>0,AVERAGE(Y10:AB10),"") | AY10: =IF(COUNTA(AC10:AF10)>0,AVERAGE(AC10:AF10),"") | AZ10: =IF(COUNTA(AG10:AJ10)>0,AVERAGE(AG10:AJ10),"") | BA10: =IF(COUNTA(AK10:AN10)>0,AVERAGE(AK10:AN10),"")
A11: 7 | B11: 6 | C11: 6 | D11: 6 | E11: 6 | F11: 6 | G11: 6 | H11: 6 | I11: 2 | J11: 5 | K11: 3 | L11: 2 | M11: 5 | N11: 5 | O11: 5 | P11: 5 | Q11: 6 | R11: 6 | S11: 6 | T11: 6 | U11: 2 | V11: 2 | W11: 2 | X11: 4 | AR11: =IF(COUNTA(A11:D11)>0,AVERAGE(A11:D11),"") -> 6.25 | AS11: =IF(COUNTA(E11:H11)>0,AVERAGE(E11:H11),"") -> 6 | AT11: =IF(COUNTA(I11:K11)>0,AVERAGE(I11:K11),"") -> 3.3333333 | AU11: =IF(COUNTA(L11:P11)>0,AVERAGE(L11:P11),"") -> 4.4 | AV11: =IF(COUNTA(Q11:T11)>0,AVERAGE(Q11:T11),"") -> 6 | AW11: =IF(COUNTA(U11:X11)>0,AVERAGE(U11:X11),"") -> 2.5 | AX11: =IF(COUNTA(Y11:AB11)>0,AVERAGE(Y11:AB11),"") | AY11: =IF(COUNTA(AC11:AF11)>0,AVERAGE(AC11:AF11),"") | AZ11: =IF(COUNTA(AG11:AJ11)>0,AVERAGE(AG11:AJ11),"") | BA11: =IF(COUNTA(AK11:AN11)>0,AVERAGE(AK11:AN11),"")
A12: 6 | B12: 7 | C12: 7 | D12: 7 | E12: 4 | F12: 3 | G12: 5 | H12: 5 | I12: 4 | J12: 5 | K12: 5 | L12: 6 | M12: 3 | N12: 4 | O12: 4 | P12: 5 | Q12: 7 | R12: 7 | S12: 7 | T12: 7 | U12: 3 | V12: 4 | W12: 4 | X12: 4 | AR12: =IF(COUNTA(A12:D12)>0,AVERAGE(A12:D12),"") -> 6.75 | AS12: =IF(COUNTA(E12:G12)>0,AVERAGE(E12:G12),"") -> 4 | AT12: =IF(COUNTA(H12:I12)>0,AVERAGE(H12:I12),"") -> 4.5 | AU12: =IF(COUNTA(J12:L12)>0,AVERAGE(J12:L12),"") -> 5.3333333 | AV12: =IF(COUNTA(N12:T12)>0,AVERAGE(N12:T12),"") -> 5.8571429 | AW12: =IF(COUNTA(U12:W12)>0,AVERAGE(U12:W12),"") -> 3.6666667 | AX12: =IF(COUNTA(X12:AB12)>0,AVERAGE(X12:AB12),"") -> 4 | AY12: =IF(COUNTA(AC12:AF12)>0,AVERAGE(AC12:AF12),"") | AZ12: =IF(COUNTA(AG12:AJ12)>0,AVERAGE(AG12:AJ12),"") | BA12: =IF(COUNTA(AK12:AN12)>0,AVERAGE(AK12:AN12),"")
A13: 5 | B13: 5 | C13: 5 | D13: 5 | E13: 5 | F13: 5 | G13: 5 | H13: 4 | I13: 4 | J13: 4 | K13: 4 | L13: 4 | M13: 5 | N13: 5 | O13: 5 | P13: 5 | Q13: 6 | R13: 6 | S13: 6 | T13: 6 | U13: 4 | V13: 4 | W13: 5 | X13: 4 | AR13: =IF(COUNTA(A13:D13)>0,AVERAGE(A13:D13),"") -> 5 | AS13: =IF(COUNTA(E13:H13)>0,AVERAGE(E13:H13),"") -> 4.75 | AT13: =IF(COUNTA(I13:L13)>0,AVERAGE(I13:L13),"") -> 4 | AU13: =IF(COUNTA(M13:P13)>0,AVERAGE(M13:P13),"") -> 5 | AV13: =IF(COUNTA(Q13:T13)>0,AVERAGE(Q13:T13),"") -> 6 | AW13: =IF(COUNTA(U13:X13)>0,AVERAGE(U13:X13),"") -> 4.25 | AX13: =IF(COUNTA(Y13:AB13)>0,AVERAGE(Y13:AB13),"") | AY13: =IF(COUNTA(AC13:AF13)>0,AVERAGE(AC13:AF13),"") | AZ13: =IF(COUNTA(AG13:AJ13)>0,AVERAGE(AG13:AJ13),"") | BA13: =IF(COUNTA(AK13:AN13)>0,AVERAGE(AK13:AN13),"")
AR14: =IF(COUNTA(A14:D14)>0,AVERAGE(A14:D14),"") | AS14: =IF(COUNTA(E14:H14)>0,AVERAGE(E14:H14),"") | AT14: =IF(COUNTA(I14:L14)>0,AVERAGE(I14:L14),"") | AU14: =IF(COUNTA(M14:P14)>0,AVERAGE(M14:P14),"") | AV14: =IF(COUNTA(Q14:T14)>0,AVERAGE(Q14:T14),"") | AW14: =IF(COUNTA(U14:X14)>0,AVERAGE(U14:X14),"") | AX14: =IF(COUNTA(Y14:AB14)>0,AVERAGE(Y14:AB14),"") | AY14: =IF(COUNTA(AC14:AF14)>0,AVERAGE(AC14:AF14),"") | AZ14: =IF(COUNTA(AG14:AJ14)>0,AVERAGE(AG14:AJ14),"") | BA14: =IF(COUNTA(AK14:AN14)>0,AVERAGE(AK14:AN14),"")
AR15: =IF(COUNTA(A15:D15)>0,AVERAGE(A15:D15),"") | AS15: =IF(COUNTA(E15:H15)>0,AVERAGE(E15:H15),"") | AT15: =IF(COUNTA(I15:L15)>0,AVERAGE(I15:L15),"") | AU15: =IF(COUNTA(M15:P15)>0,AVERAGE(M15:P15),"") | AV15: =IF(COUNTA(Q15:T15)>0,AVERAGE(Q15:T15),"") | AW15: =IF(COUNTA(U15:X15)>0,AVERAGE(U15:X15),"") | AX15: =IF(COUNTA(Y15:AB15)>0,AVERAGE(Y15:AB15),"") | AY15: =IF(COUNTA(AC15:AF15)>0,AVERAGE(AC15:AF15),"") | AZ15: =IF(COUNTA(AG15:AJ15)>0,AVERAGE(AG15:AJ15),"") | BA15: =IF(COUNTA(AK15:AN15)>0,AVERAGE(AK15:AN15),"")
AR16: =IF(COUNTA(A16:D16)>0,AVERAGE(A16:D16),"") | AS16: =IF(COUNTA(E16:H16)>0,AVERAGE(E16:H16),"") | AT16: =IF(COUNTA(I16:L16)>0,AVERAGE(I16:L16),"") | AU16: =IF(COUNTA(M16:P16)>0,AVERAGE(M16:P16),"") | AV16: =IF(COUNTA(Q16:T16)>0,AVERAGE(Q16:T16),"") | AW16: =IF(COUNTA(U16:X16)>0,AVERAGE(U16:X16),"") | AX16: =IF(COUNTA(Y16:AB16)>0,AVERAGE(Y16:AB16),"") | AY16: =IF(COUNTA(AC16:AF16)>0,AVERAGE(AC16:AF16),"") | AZ16: =IF(COUNTA(AG16:AJ16)>0,AVERAGE(AG16:AJ16),"") | BA16: =IF(COUNTA(AK16:AN16)>0,AVERAGE(AK16:AN16),"")
AR17: =IF(COUNTA(A17:D17)>0,AVERAGE(A17:D17),"") | AS17: =IF(COUNTA(E17:H17)>0,AVERAGE(E17:H17),"") | AT17: =IF(COUNTA(I17:L17)>0,AVERAGE(I17:L17),"") | AU17: =IF(COUNTA(M17:P17)>0,AVERAGE(M17:P17),"") | AV17: =IF(COUNTA(Q17:T17)>0,AVERAGE(Q17:T17),"") | AW17: =IF(COUNTA(U17:X17)>0,AVERAGE(U17:X17),"") | AX17: =IF(COUNTA(Y17:AB17)>0,AVERAGE(Y17:AB17),"") | AY17: =IF(COUNTA(AC17:AF17)>0,AVERAGE(AC17:AF17),"") | AZ17: =IF(COUNTA(AG17:AJ17)>0,AVERAGE(AG17:AJ17),"") | BA17: =IF(COUNTA(AK17:AN17)>0,AVERAGE(AK17:AN17),"")
AR18: =IF(COUNTA(A18:D18)>0,AVERAGE(A18:D18),"") | AS18: =IF(COUNTA(E18:H18)>0,AVERAGE(E18:H18),"") | AT18: =IF(COUNTA(I18:L18)>0,AVERAGE(I18:L18),"") | AU18: =IF(COUNTA(M18:P18)>0,AVERAGE(M18:P18),"") | AV18: =IF(COUNTA(Q18:T18)>0,AVERAGE(Q18:T18),"") | AW18: =IF(COUNTA(U18:X18)>0,AVERAGE(U18:X18),"") | AX18: =IF(COUNTA(Y18:AB18)>0,AVERAGE(Y18:AB18),"") | AY18: =IF(COUNTA(AC18:AF18)>0,AVERAGE(AC18:AF18),"") | AZ18: =IF(COUNTA(AG18:AJ18)>0,AVERAGE(AG18:AJ18),"") | BA18: =IF(COUNTA(AK18:AN18)>0,AVERAGE(AK18:AN18),"")
AR19: =IF(COUNTA(A19:D19)>0,AVERAGE(A19:D19),"") | AS19: =IF(COUNTA(E19:H19)>0,AVERAGE(E19:H19),"") | AT19: =IF(COUNTA(I19:L19)>0,AVERAGE(I19:L19),"") | AU19: =IF(COUNTA(M19:P19)>0,AVERAGE(M19:P19),"") | AV19: =IF(COUNTA(Q19:T19)>0,AVERAGE(Q19:T19),"") | AW19: =IF(COUNTA(U19:X19)>0,AVERAGE(U19:X19),"") | AX19: =IF(COUNTA(Y19:AB19)>0,AVERAGE(Y19:AB19),"") | AY19: =IF(COUNTA(AC19:AF19)>0,AVERAGE(AC19:AF19),"") | AZ19: =IF(COUNTA(AG19:AJ19)>0,AVERAGE(AG19:AJ19),"") | BA19: =IF(COUNTA(AK19:AN19)>0,AVERAGE(AK19:AN19),"")
AR20: =IF(COUNTA(A20:D20)>0,AVERAGE(A20:D20),"") | AS20: =IF(COUNTA(E20:H20)>0,AVERAGE(E20:H20),"") | AT20: =IF(COUNTA(I20:L20)>0,AVERAGE(I20:L20),"") | AU20: =IF(COUNTA(M20:P20)>0,AVERAGE(M20:P20),"") | AV20: =IF(COUNTA(Q20:T20)>0,AVERAGE(Q20:T20),"") | AW20: =IF(COUNTA(U20:X20)>0,AVERAGE(U20:X20),"") | AX20: =IF(COUNTA(Y20:AB20)>0,AVERAGE(Y20:AB20),"") | AY20: =IF(COUNTA(AC20:AF20)>0,AVERAGE(AC20:AF20),"") | AZ20: =IF(COUNTA(AG20:AJ20)>0,AVERAGE(AG20:AJ20),"") | BA20: =IF(COUNTA(AK20:AN20)>0,AVERAGE(AK20:AN20),"")
AR21: =IF(COUNTA(A21:D21)>0,AVERAGE(A21:D21),"") | AS21: =IF(COUNTA(E21:H21)>0,AVERAGE(E21:H21),"") | AT21: =IF(COUNTA(I21:L21)>0,AVERAGE(I21:L21),"") | AU21: =IF(COUNTA(M21:P21)>0,AVERAGE(M21:P21),"") | AV21: =IF(COUNTA(Q21:T21)>0,AVERAGE(Q21:T21),"") | AW21: =IF(COUNTA(U21:X21)>0,AVERAGE(U21:X21),"") | AX21: =IF(COUNTA(Y21:AB21)>0,AVERAGE(Y21:AB21),"") | AY21: =IF(COUNTA(AC21:AF21)>0,AVERAGE(AC21:AF21),"") | AZ21: =IF(COUNTA(AG21:AJ21)>0,AVERAGE(AG21:AJ21),"") | BA21: =IF(COUNTA(AK21:AN21)>0,AVERAGE(AK21:AN21),"")
AR22: =IF(COUNTA(A22:D22)>0,AVERAGE(A22:D22),"") | AS22: =IF(COUNTA(E22:H22)>0,AVERAGE(E22:H22),"") | AT22: =IF(COUNTA(I22:L22)>0,AVERAGE(I22:L22),"") | AU22: =IF(COUNTA(M22:P22)>0,AVERAGE(M22:P22),"") | AV22: =IF(COUNTA(Q22:T22)>0,AVERAGE(Q22:T22),"") | AW22: =IF(COUNTA(U22:X22)>0,AVERAGE(U22:X22),"") | AX22: =IF(COUNTA(Y22:AB22)>0,AVERAGE(Y22:AB22),"") | AY22: =IF(COUNTA(AC22:AF22)>0,AVERAGE(AC22:AF22),"") | AZ22: =IF(COUNTA(AG22:AJ22)>0,AVERAGE(AG22:AJ22),"") | BA22: =IF(COUNTA(AK22:AN22)>0,AVERAGE(AK22:AN22),"")
AR23: =IF(COUNTA(A23:D23)>0,AVERAGE(A23:D23),"") | AS23: =IF(COUNTA(E23:H23)>0,AVERAGE(E23:H23),"") | AT23: =IF(COUNTA(I23:L23)>0,AVERAGE(I23:L23),"") | AU23: =IF(COUNTA(M23:P23)>0,AVERAGE(M23:P23),"") | AV23: =IF(COUNTA(Q23:T23)>0,AVERAGE(Q23:T23),"") | AW23: =IF(COUNTA(U23:X23)>0,AVERAGE(U23:X23),"") | AX23: =IF(COUNTA(Y23:AB23)>0,AVERAGE(Y23:AB23),"") | AY23: =IF(COUNTA(AC23:AF23)>0,AVERAGE(AC23:AF23),"") | AZ23: =IF(COUNTA(AG23:AJ23)>0,AVERAGE(AG23:AJ23),"") | BA23: =IF(COUNTA(AK23:AN23)>0,AVERAGE(AK23:AN23),"")
AR24: =IF(COUNTA(A24:D24)>0,AVERAGE(A24:D24),"") | AS24: =IF(COUNTA(E24:H24)>0,AVERAGE(E24:H24),"") | AT24: =IF(COUNTA(I24:L24)>0,AVERAGE(I24:L24),"") | AU24: =IF(COUNTA(M24:P24)>0,AVERAGE(M24:P24),"") | AV24: =IF(COUNTA(Q24:T24)>0,AVERAGE(Q24:T24),"") | AW24: =IF(COUNTA(U24:X24)>0,AVERAGE(U24:X24),"") | AX24: =IF(COUNTA(Y24:AB24)>0,AVERAGE(Y24:AB24),"") | AY24: =IF(COUNTA(AC24:AF24)>0,AVERAGE(AC24:AF24),"") | AZ24: =IF(COUNTA(AG24:AJ24)>0,AVERAGE(AG24:AJ24),"") | BA24: =IF(COUNTA(AK24:AN24)>0,AVERAGE(AK24:AN24),"")
AR25: =IF(COUNTA(A25:D25)>0,AVERAGE(A25:D25),"") | AS25: =IF(COUNTA(E25:H25)>0,AVERAGE(E25:H25),"") | AT25: =IF(COUNTA(I25:L25)>0,AVERAGE(I25:L25),"") | AU25: =IF(COUNTA(M25:P25)>0,AVERAGE(M25:P25),"") | AV25: =IF(COUNTA(Q25:T25)>0,AVERAGE(Q25:T25),"") | AW25: =IF(COUNTA(U25:X25)>0,AVERAGE(U25:X25),"") | AX25: =IF(COUNTA(Y25:AB25)>0,AVERAGE(Y25:AB25),"") | AY25: =IF(COUNTA(AC25:AF25)>0,AVERAGE(AC25:AF25),"") | AZ25: =IF(COUNTA(AG25:AJ25)>0,AVERAGE(AG25:AJ25),"") | BA25: =IF(COUNTA(AK25:AN25)>0,AVERAGE(AK25:AN25),"")
... AR1004: =IF(COUNTA(A1004:D1004)>0,AVERAGE(A1004:D1004),"") | AS1004: =IF(COUNTA(E1004:H1004)>0,AVERAGE(E1004:H1004),"") | AT1004: =IF(COUNTA(I1004:L1004)>0,AVERAGE(I1004:L1004),"") | AU1004: =IF(COUNTA(M1004:P1004)>0,AVERAGE(M1004:P1004),"") | AV1004: =IF(COUNTA(Q1004:T1004)>0,AVERAGE(Q1004:T1004),"") | AW1004: =IF(COUNTA(U1004:X1004)>0,AVERAGE(U1004:X1004),"") | AX1004: =IF(COUNTA(Y1004:AB1004)>0,AVERAGE(Y1004:AB1004),"") | AY1004: =IF(COUNTA(AC1004:AF1004)>0,AVERAGE(AC1004:AF1004),"") | AZ1004: =IF(COUNTA(AG1004:AJ1004)>0,AVERAGE(AG1004:AJ1004),"") | BA1004: =IF(COUNTA(AK1004:AN1004)>0,AVERAGE(AK1004:AN1004),"")

Sheet Data_Importance
A1: Please enter the data for the importance ratings here! For each scale the UEQ+ collects ratings for 4 items and one rating for the overall importance of the scale. Please enter the importance ratings here. Use the values 1 (if the alternative on the extreme left is marked) to 7 (if the alternative on the extreme right is marked). Leave the cell empty if the person has not answered the item. Please do not enter a special caracter in such cases, since this would cause errors in the calculations. You can enter data for a maximum of 1000 participants. If you need more, you have to adjust the fomulas in the Excel.
A2: Enter the observed importance ratings here | L2: Relative Importance Ratings (Calculated, do not modify the cells below)
A3: =Data_Items!A3 -> Intuitive Use | B3: =Data_Items!E3 -> Trustworthiness of Content | C3: =Data_Items!I3 -> Response Behavior | D3: =Data_Items!M3 -> Response Quality | E3: =Data_Items!Q3 -> Clarity | F3: =Data_Items!U3 -> Risk Handling | G3: =Data_Items!Y3 -> Choose Scale | H3: =Data_Items!AC3 -> Choose Scale | I3: =Data_Items!AG3 -> Choose Scale | J3: =Data_Items!AK3 -> Choose Scale | L3: =A3 -> Intuitive Use | M3: =B3 -> Trustworthiness of Content | N3: =C3 -> Response Behavior | O3: =D3 -> Response Quality | P3: =E3 -> Clarity | Q3: =F3 -> Risk Handling | R3: =G3 -> Choose Scale | S3: =H3 -> Choose Scale | ... U3: =J3 -> Choose Scale
A4: 5 | B4: 6 | C4: 7 | D4: 3 | E4: 5 | F4: 5 | G4: 6 | L4: =IF(A4="","",A4/SUM(A4:J4)) -> 0.13513514 | M4: =IF(B4="","",B4/SUM(A4:J4)) -> 0.16216216 | N4: =IF(C4="","",C4/SUM(A4:J4)) -> 0.18918919 | O4: =IF(D4="","",D4/SUM(A4:J4)) -> 0.081081081 | P4: =IF(E4="","",E4/SUM(A4:J4)) -> 0.13513514 | Q4: =IF(F4="","",F4/SUM(A4:J4)) -> 0.13513514 | R4: =IF(G4="","",G4/SUM(A4:J4)) -> 0.16216216 | S4: =IF(H4="","",H4/SUM(A4:J4)) | T4: =IF(I4="","",I4/SUM(A4:J4)) | U4: =IF(J4="","",J4/SUM(A4:J4))
A5: 5 | C5: 7 | D5: 6 | E5: 7 | F5: 7 | G5: 7 | L5: =IF(A5="","",A5/SUM(A5:J5)) -> 0.12820513 | M5: =IF(B5="","",B5/SUM(A5:J5)) | N5: =IF(C5="","",C5/SUM(A5:J5)) -> 0.17948718 | O5: =IF(D5="","",D5/SUM(A5:J5)) -> 0.15384615 | P5: =IF(E5="","",E5/SUM(A5:J5)) -> 0.17948718 | Q5: =IF(F5="","",F5/SUM(A5:J5)) -> 0.17948718 | R5: =IF(G5="","",G5/SUM(A5:J5)) -> 0.17948718 | S5: =IF(H5="","",H5/SUM(A5:J5)) | T5: =IF(I5="","",I5/SUM(A5:J5)) | U5: =IF(J5="","",J5/SUM(A5:J5))
A6: 5 | B6: 7 | C6: 4 | D6: 6 | E6: 4 | F6: 4 | G6: 4 | L6: =IF(A6="","",A6/SUM(A6:J6)) -> 0.14705882 | M6: =IF(B6="","",B6/SUM(A6:J6)) -> 0.20588235 | N6: =IF(C6="","",C6/SUM(A6:J6)) -> 0.11764706 | O6: =IF(D6="","",D6/SUM(A6:J6)) -> 0.17647059 | P6: =IF(E6="","",E6/SUM(A6:J6)) -> 0.11764706 | Q6: =IF(F6="","",F6/SUM(A6:J6)) -> 0.11764706 | R6: =IF(G6="","",G6/SUM(A6:J6)) -> 0.11764706 | S6: =IF(H6="","",H6/SUM(A6:J6)) | T6: =IF(I6="","",I6/SUM(A6:J6)) | U6: =IF(J6="","",J6/SUM(A6:J6))
A7: 6 | B7: 4 | C7: 4 | D7: 3 | E7: 5 | F7: 5 | G7: 4 | L7: =IF(A7="","",A7/SUM(A7:J7)) -> 0.19354839 | M7: =IF(B7="","",B7/SUM(A7:J7)) -> 0.12903226 | N7: =IF(C7="","",C7/SUM(A7:J7)) -> 0.12903226 | O7: =IF(D7="","",D7/SUM(A7:J7)) -> 0.096774194 | P7: =IF(E7="","",E7/SUM(A7:J7)) -> 0.16129032 | Q7: =IF(F7="","",F7/SUM(A7:J7)) -> 0.16129032 | R7: =IF(G7="","",G7/SUM(A7:J7)) -> 0.12903226 | S7: =IF(H7="","",H7/SUM(A7:J7)) | T7: =IF(I7="","",I7/SUM(A7:J7)) | U7: =IF(J7="","",J7/SUM(A7:J7))
A8: 6 | B8: 7 | C8: 6 | D8: 5 | E8: 5 | F8: 6 | G8: 6 | L8: =IF(A8="","",A8/SUM(A8:J8)) -> 0.14634146 | M8: =IF(B8="","",B8/SUM(A8:J8)) -> 0.17073171 | N8: =IF(C8="","",C8/SUM(A8:J8)) -> 0.14634146 | O8: =IF(D8="","",D8/SUM(A8:J8)) -> 0.12195122 | P8: =IF(E8="","",E8/SUM(A8:J8)) -> 0.12195122 | Q8: =IF(F8="","",F8/SUM(A8:J8)) -> 0.14634146 | R8: =IF(G8="","",G8/SUM(A8:J8)) -> 0.14634146 | S8: =IF(H8="","",H8/SUM(A8:J8)) | T8: =IF(I8="","",I8/SUM(A8:J8)) | U8: =IF(J8="","",J8/SUM(A8:J8))
A9: 7 | B9: 7 | C9: 7 | D9: 7 | E9: 7 | F9: 7 | G9: 7 | L9: =IF(A9="","",A9/SUM(A9:J9)) -> 0.14285714 | M9: =IF(B9="","",B9/SUM(A9:J9)) -> 0.14285714 | N9: =IF(C9="","",C9/SUM(A9:J9)) -> 0.14285714 | O9: =IF(D9="","",D9/SUM(A9:J9)) -> 0.14285714 | P9: =IF(E9="","",E9/SUM(A9:J9)) -> 0.14285714 | Q9: =IF(F9="","",F9/SUM(A9:J9)) -> 0.14285714 | R9: =IF(G9="","",G9/SUM(A9:J9)) -> 0.14285714 | S9: =IF(H9="","",H9/SUM(A9:J9)) | T9: =IF(I9="","",I9/SUM(A9:J9)) | U9: =IF(J9="","",J9/SUM(A9:J9))
A10: 5 | B10: 6 | C10: 5 | D10: 6 | E10: 6 | F10: 6 | G10: 5 | L10: =IF(A10="","",A10/SUM(A10:J10)) -> 0.12820513 | M10: =IF(B10="","",B10/SUM(A10:J10)) -> 0.15384615 | N10: =IF(C10="","",C10/SUM(A10:J10)) -> 0.12820513 | O10: =IF(D10="","",D10/SUM(A10:J10)) -> 0.15384615 | P10: =IF(E10="","",E10/SUM(A10:J10)) -> 0.15384615 | Q10: =IF(F10="","",F10/SUM(A10:J10)) -> 0.15384615 | R10: =IF(G10="","",G10/SUM(A10:J10)) -> 0.12820513 | S10: =IF(H10="","",H10/SUM(A10:J10)) | T10: =IF(I10="","",I10/SUM(A10:J10)) | U10: =IF(J10="","",J10/SUM(A10:J10))
A11: 6 | B11: 6 | C11: 6 | D11: 3 | E11: 4 | F11: 5 | G11: 5 | L11: =IF(A11="","",A11/SUM(A11:J11)) -> 0.17142857 | M11: =IF(B11="","",B11/SUM(A11:J11)) -> 0.17142857 | N11: =IF(C11="","",C11/SUM(A11:J11)) -> 0.17142857 | O11: =IF(D11="","",D11/SUM(A11:J11)) -> 0.085714286 | P11: =IF(E11="","",E11/SUM(A11:J11)) -> 0.11428571 | Q11: =IF(F11="","",F11/SUM(A11:J11)) -> 0.14285714 | R11: =IF(G11="","",G11/SUM(A11:J11)) -> 0.14285714 | S11: =IF(H11="","",H11/SUM(A11:J11)) | T11: =IF(I11="","",I11/SUM(A11:J11)) | U11: =IF(J11="","",J11/SUM(A11:J11))
A12: 4 | B12: 5 | C12: 4 | D12: 4 | E12: 5 | F12: 5 | G12: 5 | L12: =IF(A12="","",A12/SUM(A12:J12)) -> 0.125 | M12: =IF(B12="","",B12/SUM(A12:J12)) -> 0.15625 | N12: =IF(C12="","",C12/SUM(A12:J12)) -> 0.125 | O12: =IF(D12="","",D12/SUM(A12:J12)) -> 0.125 | P12: =IF(E12="","",E12/SUM(A12:J12)) -> 0.15625 | Q12: =IF(F12="","",F12/SUM(A12:J12)) -> 0.15625 | R12: =IF(G12="","",G12/SUM(A12:J12)) -> 0.15625 | S12: =IF(H12="","",H12/SUM(A12:J12)) | T12: =IF(I12="","",I12/SUM(A12:J12)) | U12: =IF(J12="","",J12/SUM(A12:J12))
A13: 5 | B13: 7 | C13: 7 | D13: 6 | E13: 5 | F13: 5 | G13: 6 | L13: =IF(A13="","",A13/SUM(A13:J13)) -> 0.12195122 | M13: =IF(B13="","",B13/SUM(A13:J13)) -> 0.17073171 | N13: =IF(C13="","",C13/SUM(A13:J13)) -> 0.17073171 | O13: =IF(D13="","",D13/SUM(A13:J13)) -> 0.14634146 | P13: =IF(E13="","",E13/SUM(A13:J13)) -> 0.12195122 | Q13: =IF(F13="","",F13/SUM(A13:J13)) -> 0.12195122 | R13: =IF(G13="","",G13/SUM(A13:J13)) -> 0.14634146 | S13: =IF(H13="","",H13/SUM(A13:J13)) | T13: =IF(I13="","",I13/SUM(A13:J13)) | U13: =IF(J13="","",J13/SUM(A13:J13))
A14: 6 | B14: 7 | C14: 5 | D14: 4 | E14: 6 | F14: 6 | G14: 7 | L14: =IF(A14="","",A14/SUM(A14:J14)) -> 0.14634146 | M14: =IF(B14="","",B14/SUM(A14:J14)) -> 0.17073171 | N14: =IF(C14="","",C14/SUM(A14:J14)) -> 0.12195122 | O14: =IF(D14="","",D14/SUM(A14:J14)) -> 0.097560976 | P14: =IF(E14="","",E14/SUM(A14:J14)) -> 0.14634146 | Q14: =IF(F14="","",F14/SUM(A14:J14)) -> 0.14634146 | R14: =IF(G14="","",G14/SUM(A14:J14)) -> 0.17073171 | S14: =IF(H14="","",H14/SUM(A14:J14)) | T14: =IF(I14="","",I14/SUM(A14:J14)) | U14: =IF(J14="","",J14/SUM(A14:J14))
A15: 6 | B15: 7 | C15: 6 | D15: 7 | E15: 7 | F15: 6 | G15: 4 | L15: =IF(A15="","",A15/SUM(A15:J15)) -> 0.13953488 | M15: =IF(B15="","",B15/SUM(A15:J15)) -> 0.1627907 | N15: =IF(C15="","",C15/SUM(A15:J15)) -> 0.13953488 | O15: =IF(D15="","",D15/SUM(A15:J15)) -> 0.1627907 | P15: =IF(E15="","",E15/SUM(A15:J15)) -> 0.1627907 | Q15: =IF(F15="","",F15/SUM(A15:J15)) -> 0.13953488 | R15: =IF(G15="","",G15/SUM(A15:J15)) -> 0.093023256 | S15: =IF(H15="","",H15/SUM(A15:J15)) | T15: =IF(I15="","",I15/SUM(A15:J15)) | U15: =IF(J15="","",J15/SUM(A15:J15))
A16: 5 | B16: 6 | C16: 4 | D16: 4 | E16: 5 | F16: 6 | G16: 6 | L16: =IF(A16="","",A16/SUM(A16:J16)) -> 0.13888889 | M16: =IF(B16="","",B16/SUM(A16:J16)) -> 0.16666667 | N16: =IF(C16="","",C16/SUM(A16:J16)) -> 0.11111111 | O16: =IF(D16="","",D16/SUM(A16:J16)) -> 0.11111111 | P16: =IF(E16="","",E16/SUM(A16:J16)) -> 0.13888889 | Q16: =IF(F16="","",F16/SUM(A16:J16)) -> 0.16666667 | R16: =IF(G16="","",G16/SUM(A16:J16)) -> 0.16666667 | S16: =IF(H16="","",H16/SUM(A16:J16)) | T16: =IF(I16="","",I16/SUM(A16:J16)) | U16: =IF(J16="","",J16/SUM(A16:J16))
A17: 5 | B17: 5 | C17: 5 | D17: 5 | E17: 5 | F17: 5 | G17: 5 | L17: =IF(A17="","",A17/SUM(A17:J17)) -> 0.14285714 | M17: =IF(B17="","",B17/SUM(A17:J17)) -> 0.14285714 | N17: =IF(C17="","",C17/SUM(A17:J17)) -> 0.14285714 | O17: =IF(D17="","",D17/SUM(A17:J17)) -> 0.14285714 | P17: =IF(E17="","",E17/SUM(A17:J17)) -> 0.14285714 | Q17: =IF(F17="","",F17/SUM(A17:J17)) -> 0.14285714 | R17: =IF(G17="","",G17/SUM(A17:J17)) -> 0.14285714 | S17: =IF(H17="","",H17/SUM(A17:J17)) | T17: =IF(I17="","",I17/SUM(A17:J17)) | U17: =IF(J17="","",J17/SUM(A17:J17))
... A25: 7 | B25: 7 | C25: 5 | D25: 7 | E25: 5 | F25: 5 | G25: 6 | L25: =IF(A25="","",A25/SUM(A25:J25)) -> 0.16666667 | M25: =IF(B25="","",B25/SUM(A25:J25)) -> 0.16666667 | N25: =IF(C25="","",C25/SUM(A25:J25)) -> 0.11904762 | O25: =IF(D25="","",D25/SUM(A25:J25)) -> 0.16666667 | P25: =IF(E25="","",E25/SUM(A25:J25)) -> 0.11904762 | Q25: =IF(F25="","",F25/SUM(A25:J25)) -> 0.11904762 | R25: =IF(G25="","",G25/SUM(A25:J25)) -> 0.14285714 | S25: =IF(H25="","",H25/SUM(A25:J25)) | T25: =IF(I25="","",I25/SUM(A25:J25)) | U25: =IF(J25="","",J25/SUM(A25:J25))
A26: 4 | B26: 6 | C26: 7 | E26: 4 | F26: 5 | G26: 6 | L26: =IF(A26="","",A26/SUM(A26:J26)) -> 0.125 | M26: =IF(B26="","",B26/SUM(A26:J26)) -> 0.1875 | N26: =IF(C26="","",C26/SUM(A26:J26)) -> 0.21875 | O26: =IF(D26="","",D26/SUM(A26:J26)) | P26: =IF(E26="","",E26/SUM(A26:J26)) -> 0.125 | Q26: =IF(F26="","",F26/SUM(A26:J26)) -> 0.15625 | R26: =IF(G26="","",G26/SUM(A26:J26)) -> 0.1875 | S26: =IF(H26="","",H26/SUM(A26:J26)) | T26: =IF(I26="","",I26/SUM(A26:J26)) | U26: =IF(J26="","",J26/SUM(A26:J26))
A27: 5 | B27: 7 | C27: 7 | D27: 5 | E27: 7 | F27: 6 | G27: 7 | L27: =IF(A27="","",A27/SUM(A27:J27)) -> 0.11363636 | M27: =IF(B27="","",B27/SUM(A27:J27)) -> 0.15909091 | N27: =IF(C27="","",C27/SUM(A27:J27)) -> 0.15909091 | O27: =IF(D27="","",D27/SUM(A27:J27)) -> 0.11363636 | P27: =IF(E27="","",E27/SUM(A27:J27)) -> 0.15909091 | Q27: =IF(F27="","",F27/SUM(A27:J27)) -> 0.13636364 | R27: =IF(G27="","",G27/SUM(A27:J27)) -> 0.15909091 | S27: =IF(H27="","",H27/SUM(A27:J27)) | T27: =IF(I27="","",I27/SUM(A27:J27)) | U27: =IF(J27="","",J27/SUM(A27:J27))
A28: 5 | B28: 7 | C28: 6 | D28: 4 | E28: 5 | F28: 6 | G28: 5 | L28: =IF(A28="","",A28/SUM(A28:J28)) -> 0.13157895 | M28: =IF(B28="","",B28/SUM(A28:J28)) -> 0.18421053 | N28: =IF(C28="","",C28/SUM(A28:J28)) -> 0.15789474 | O28: =IF(D28="","",D28/SUM(A28:J28)) -> 0.10526316 | P28: =IF(E28="","",E28/SUM(A28:J28)) -> 0.13157895 | Q28: =IF(F28="","",F28/SUM(A28:J28)) -> 0.15789474 | R28: =IF(G28="","",G28/SUM(A28:J28)) -> 0.13157895 | S28: =IF(H28="","",H28/SUM(A28:J28)) | T28: =IF(I28="","",I28/SUM(A28:J28)) | U28: =IF(J28="","",J28/SUM(A28:J28))
A29: 6 | B29: 5 | C29: 5 | D29: 4 | E29: 6 | F29: 7 | G29: 5 | L29: =IF(A29="","",A29/SUM(A29:J29)) -> 0.15789474 | M29: =IF(B29="","",B29/SUM(A29:J29)) -> 0.13157895 | N29: =IF(C29="","",C29/SUM(A29:J29)) -> 0.13157895 | O29: =IF(D29="","",D29/SUM(A29:J29)) -> 0.10526316 | P29: =IF(E29="","",E29/SUM(A29:J29)) -> 0.15789474 | Q29: =IF(F29="","",F29/SUM(A29:J29)) -> 0.18421053 | R29: =IF(G29="","",G29/SUM(A29:J29)) -> 0.13157895 | S29: =IF(H29="","",H29/SUM(A29:J29)) | T29: =IF(I29="","",I29/SUM(A29:J29)) | U29: =IF(J29="","",J29/SUM(A29:J29))
A30: 6 | B30: 6 | C30: 6 | D30: 5 | E30: 6 | F30: 4 | G30: 6 | L30: =IF(A30="","",A30/SUM(A30:J30)) -> 0.15384615 | M30: =IF(B30="","",B30/SUM(A30:J30)) -> 0.15384615 | N30: =IF(C30="","",C30/SUM(A30:J30)) -> 0.15384615 | O30: =IF(D30="","",D30/SUM(A30:J30)) -> 0.12820513 | P30: =IF(E30="","",E30/SUM(A30:J30)) -> 0.15384615 | Q30: =IF(F30="","",F30/SUM(A30:J30)) -> 0.1025641 | R30: =IF(G30="","",G30/SUM(A30:J30)) -> 0.15384615 | S30: =IF(H30="","",H30/SUM(A30:J30)) | T30: =IF(I30="","",I30/SUM(A30:J30)) | U30: =IF(J30="","",J30/SUM(A30:J30))
A31: 7 | B31: 7 | C31: 7 | D31: 7 | E31: 7 | F31: 7 | G31: 7 | L31: =IF(A31="","",A31/SUM(A31:J31)) -> 0.14285714 | M31: =IF(B31="","",B31/SUM(A31:J31)) -> 0.14285714 | N31: =IF(C31="","",C31/SUM(A31:J31)) -> 0.14285714 | O31: =IF(D31="","",D31/SUM(A31:J31)) -> 0.14285714 | P31: =IF(E31="","",E31/SUM(A31:J31)) -> 0.14285714 | Q31: =IF(F31="","",F31/SUM(A31:J31)) -> 0.14285714 | R31: =IF(G31="","",G31/SUM(A31:J31)) -> 0.14285714 | S31: =IF(H31="","",H31/SUM(A31:J31)) | T31: =IF(I31="","",I31/SUM(A31:J31)) | U31: =IF(J31="","",J31/SUM(A31:J31))
A32: 6 | B32: 7 | C32: 6 | D32: 6 | E32: 6 | F32: 7 | G32: 6 | L32: =IF(A32="","",A32/SUM(A32:J32)) -> 0.13636364 | M32: =IF(B32="","",B32/SUM(A32:J32)) -> 0.15909091 | N32: =IF(C32="","",C32/SUM(A32:J32)) -> 0.13636364 | O32: =IF(D32="","",D32/SUM(A32:J32)) -> 0.13636364 | P32: =IF(E32="","",E32/SUM(A32:J32)) -> 0.13636364 | Q32: =IF(F32="","",F32/SUM(A32:J32)) -> 0.15909091 | R32: =IF(G32="","",G32/SUM(A32:J32)) -> 0.13636364 | S32: =IF(H32="","",H32/SUM(A32:J32)) | T32: =IF(I32="","",I32/SUM(A32:J32)) | U32: =IF(J32="","",J32/SUM(A32:J32))
A33: 5 | B33: 7 | C33: 4 | D33: 5 | E33: 4 | F33: 4 | G33: 7 | L33: =IF(A33="","",A33/SUM(A33:J33)) -> 0.13888889 | M33: =IF(B33="","",B33/SUM(A33:J33)) -> 0.19444444 | N33: =IF(C33="","",C33/SUM(A33:J33)) -> 0.11111111 | O33: =IF(D33="","",D33/SUM(A33:J33)) -> 0.13888889 | P33: =IF(E33="","",E33/SUM(A33:J33)) -> 0.11111111 | Q33: =IF(F33="","",F33/SUM(A33:J33)) -> 0.11111111 | R33: =IF(G33="","",G33/SUM(A33:J33)) -> 0.19444444 | S33: =IF(H33="","",H33/SUM(A33:J33)) | T33: =IF(I33="","",I33/SUM(A33:J33)) | U33: =IF(J33="","",J33/SUM(A33:J33))
A34: 6 | B34: 5 | C34: 5 | D34: 5 | E34: 5 | F34: 5 | G34: 5 | L34: =IF(A34="","",A34/SUM(A34:J34)) -> 0.16666667 | M34: =IF(B34="","",B34/SUM(A34:J34)) -> 0.13888889 | N34: =IF(C34="","",C34/SUM(A34:J34)) -> 0.13888889 | O34: =IF(D34="","",D34/SUM(A34:J34)) -> 0.13888889 | P34: =IF(E34="","",E34/SUM(A34:J34)) -> 0.13888889 | Q34: =IF(F34="","",F34/SUM(A34:J34)) -> 0.13888889 | R34: =IF(G34="","",G34/SUM(A34:J34)) -> 0.13888889 | S34: =IF(H34="","",H34/SUM(A34:J34)) | T34: =IF(I34="","",I34/SUM(A34:J34)) | U34: =IF(J34="","",J34/SUM(A34:J34))
L35: =IF(A35="","",A35/SUM(A35:J35)) | M35: =IF(B35="","",B35/SUM(A35:J35)) | N35: =IF(C35="","",C35/SUM(A35:J35)) | O35: =IF(D35="","",D35/SUM(A35:J35)) | P35: =IF(E35="","",E35/SUM(A35:J35)) | Q35: =IF(F35="","",F35/SUM(A35:J35)) | R35: =IF(G35="","",G35/SUM(A35:J35)) | S35: =IF(H35="","",H35/SUM(A35:J35)) | T35: =IF(I35="","",I35/SUM(A35:J35)) | U35: =IF(J35="","",J35/SUM(A35:J35))
L36: =IF(A36="","",A36/SUM(A36:J36)) | M36: =IF(B36="","",B36/SUM(A36:J36)) | N36: =IF(C36="","",C36/SUM(A36:J36)) | O36: =IF(D36="","",D36/SUM(A36:J36)) | P36: =IF(E36="","",E36/SUM(A36:J36)) | Q36: =IF(F36="","",F36/SUM(A36:J36)) | R36: =IF(G36="","",G36/SUM(A36:J36)) | S36: =IF(H36="","",H36/SUM(A36:J36)) | T36: =IF(I36="","",I36/SUM(A36:J36)) | U36: =IF(J36="","",J36/SUM(A36:J36))
L37: =IF(A37="","",A37/SUM(A37:J37)) | M37: =IF(B37="","",B37/SUM(A37:J37)) | N37: =IF(C37="","",C37/SUM(A37:J37)) | O37: =IF(D37="","",D37/SUM(A37:J37)) | P37: =IF(E37="","",E37/SUM(A37:J37)) | Q37: =IF(F37="","",F37/SUM(A37:J37)) | R37: =IF(G37="","",G37/SUM(A37:J37)) | S37: =IF(H37="","",H37/SUM(A37:J37)) | T37: =IF(I37="","",I37/SUM(A37:J37)) | U37: =IF(J37="","",J37/SUM(A37:J37))
L38: =IF(A38="","",A38/SUM(A38:J38)) | M38: =IF(B38="","",B38/SUM(A38:J38)) | N38: =IF(C38="","",C38/SUM(A38:J38)) | O38: =IF(D38="","",D38/SUM(A38:J38)) | P38: =IF(E38="","",E38/SUM(A38:J38)) | Q38: =IF(F38="","",F38/SUM(A38:J38)) | R38: =IF(G38="","",G38/SUM(A38:J38)) | S38: =IF(H38="","",H38/SUM(A38:J38)) | T38: =IF(I38="","",I38/SUM(A38:J38)) | U38: =IF(J38="","",J38/SUM(A38:J38))
L39: =IF(A39="","",A39/SUM(A39:J39)) | M39: =IF(B39="","",B39/SUM(A39:J39)) | N39: =IF(C39="","",C39/SUM(A39:J39)) | O39: =IF(D39="","",D39/SUM(A39:J39)) | P39: =IF(E39="","",E39/SUM(A39:J39)) | Q39: =IF(F39="","",F39/SUM(A39:J39)) | R39: =IF(G39="","",G39/SUM(A39:J39)) | S39: =IF(H39="","",H39/SUM(A39:J39)) | T39: =IF(I39="","",I39/SUM(A39:J39)) | U39: =IF(J39="","",J39/SUM(A39:J39))
L40: =IF(A40="","",A40/SUM(A40:J40)) | M40: =IF(B40="","",B40/SUM(A40:J40)) | N40: =IF(C40="","",C40/SUM(A40:J40)) | O40: =IF(D40="","",D40/SUM(A40:J40)) | P40: =IF(E40="","",E40/SUM(A40:J40)) | Q40: =IF(F40="","",F40/SUM(A40:J40)) | R40: =IF(G40="","",G40/SUM(A40:J40)) | S40: =IF(H40="","",H40/SUM(A40:J40)) | T40: =IF(I40="","",I40/SUM(A40:J40)) | U40: =IF(J40="","",J40/SUM(A40:J40))
L41: =IF(A41="","",A41/SUM(A41:J41)) | M41: =IF(B41="","",B41/SUM(A41:J41)) | N41: =IF(C41="","",C41/SUM(A41:J41)) | O41: =IF(D41="","",D41/SUM(A41:J41)) | P41: =IF(E41="","",E41/SUM(A41:J41)) | Q41: =IF(F41="","",F41/SUM(A41:J41)) | R41: =IF(G41="","",G41/SUM(A41:J41)) | S41: =IF(H41="","",H41/SUM(A41:J41)) | T41: =IF(I41="","",I41/SUM(A41:J41)) | U41: =IF(J41="","",J41/SUM(A41:J41))
L42: =IF(A42="","",A42/SUM(A42:J42)) | M42: =IF(B42="","",B42/SUM(A42:J42)) | N42: =IF(C42="","",C42/SUM(A42:J42)) | O42: =IF(D42="","",D42/SUM(A42:J42)) | P42: =IF(E42="","",E42/SUM(A42:J42)) | Q42: =IF(F42="","",F42/SUM(A42:J42)) | R42: =IF(G42="","",G42/SUM(A42:J42)) | S42: =IF(H42="","",H42/SUM(A42:J42)) | T42: =IF(I42="","",I42/SUM(A42:J42)) | U42: =IF(J42="","",J42/SUM(A42:J42))
L43: =IF(A43="","",A43/SUM(A43:J43)) | M43: =IF(B43="","",B43/SUM(A43:J43)) | N43: =IF(C43="","",C43/SUM(A43:J43)) | O43: =IF(D43="","",D43/SUM(A43:J43)) | P43: =IF(E43="","",E43/SUM(A43:J43)) | Q43: =IF(F43="","",F43/SUM(A43:J43)) | R43: =IF(G43="","",G43/SUM(A43:J43)) | S43: =IF(H43="","",H43/SUM(A43:J43)) | T43: =IF(I43="","",I43/SUM(A43:J43)) | U43: =IF(J43="","",J43/SUM(A43:J43))
L44: =IF(A44="","",A44/SUM(A44:J44)) | M44: =IF(B44="","",B44/SUM(A44:J44)) | N44: =IF(C44="","",C44/SUM(A44:J44)) | O44: =IF(D44="","",D44/SUM(A44:J44)) | P44: =IF(E44="","",E44/SUM(A44:J44)) | Q44: =IF(F44="","",F44/SUM(A44:J44)) | R44: =IF(G44="","",G44/SUM(A44:J44)) | S44: =IF(H44="","",H44/SUM(A44:J44)) | T44: =IF(I44="","",I44/SUM(A44:J44)) | U44: =IF(J44="","",J44/SUM(A44:J44))
L45: =IF(A45="","",A45/SUM(A45:J45)) | M45: =IF(B45="","",B45/SUM(A45:J45)) | N45: =IF(C45="","",C45/SUM(A45:J45)) | O45: =IF(D45="","",D45/SUM(A45:J45)) | P45: =IF(E45="","",E45/SUM(A45:J45)) | Q45: =IF(F45="","",F45/SUM(A45:J45)) | R45: =IF(G45="","",G45/SUM(A45:J45)) | S45: =IF(H45="","",H45/SUM(A45:J45)) | T45: =IF(I45="","",I45/SUM(A45:J45)) | U45: =IF(J45="","",J45/SUM(A45:J45))
L46: =IF(A46="","",A46/SUM(A46:J46)) | M46: =IF(B46="","",B46/SUM(A46:J46)) | N46: =IF(C46="","",C46/SUM(A46:J46)) | O46: =IF(D46="","",D46/SUM(A46:J46)) | P46: =IF(E46="","",E46/SUM(A46:J46)) | Q46: =IF(F46="","",F46/SUM(A46:J46)) | R46: =IF(G46="","",G46/SUM(A46:J46)) | S46: =IF(H46="","",H46/SUM(A46:J46)) | T46: =IF(I46="","",I46/SUM(A46:J46)) | U46: =IF(J46="","",J46/SUM(A46:J46))
... L1004: =IF(A1004="","",A1004/SUM(A1004:J1004)) | M1004: =IF(B1004="","",B1004/SUM(A1004:J1004)) | N1004: =IF(C1004="","",C1004/SUM(A1004:J1004)) | O1004: =IF(D1004="","",D1004/SUM(A1004:J1004)) | P1004: =IF(E1004="","",E1004/SUM(A1004:J1004)) | Q1004: =IF(F1004="","",F1004/SUM(A1004:J1004)) | R1004: =IF(G1004="","",G1004/SUM(A1004:J1004)) | S1004: =IF(H1004="","",H1004/SUM(A1004:J1004)) | T1004: =IF(I1004="","",I1004/SUM(A1004:J1004)) | U1004: =IF(J1004="","",J1004/SUM(A1004:J1004))

Sheet Means
A1: Mean and Standard Deviation per Scale and per Item
A2: Here means for the scales (mean over all items in a scale), standard deviations and confidence intervalls are calculated. The mean values are transformed from a 1 to 7 range to a -3 to +3 range to be compatible with the reporting format of the original UEQ.
A4: Mean and Confidence Interval per Scale | J4: Mean and Confidence Interval per Item
A5: Scale | B5: Mean | C5: Variance | D5: Std.dev. | E5: N | F5: Confidence | G5: Confidence Interval | J5: Scale | K5: Item Left | L5: Item Right | M5: Mean | N5: Variance | O5: Std.dev. | P5: N | Q5: Confidence | R5: Confidence Intervall
A6: =IF(Data_Items!A3="Choose Scale","",Data_Items!A3) -> Intuitive Use | B6: =IF(Data_Items!A3="Choose Scale","",AVERAGE(Data_Items!A4:D1004)-4) -> 2.375 | C6: =IF(Data_Items!A3="Choose Scale","",VAR(Data_Items!A4:D1004)) -> 0.75320513 | D6: =IF(Data_Items!A3="Choose Scale","",_xlfn.STDEV.P(Data_Items!A4:D1004)) -> 0.85695683 | E6: =IF(A6="","",MAX(P6:P45)) -> 10 | F6: =IF(A6="","",CONFIDENCE(0.05, D6, E6)) -> 0.53113758 | G6: =IF(A6="","",B6-F6) -> 1.8438624 | H6: =IF(A6="","",B6+F6) -> 2.9061376 | J6: =A6 -> Intuitive Use | K6: =IF(A6="","",VLOOKUP(A6,Texts!A1:I30,2,FALSE)) -> difficult | L6: =IF(A6="","",VLOOKUP(A6,Texts!A1:I30,3,FALSE)) -> easy | M6: =IF(K6="","",AVERAGE(Data_Items!A4:A1004)-4) -> 2.5 | N6: =IF(K6="","",VAR(Data_Items!A4:A1004)) -> 0.5 | O6: =IF(K6="","",_xlfn.STDEV.P(Data_Items!A4:A1004)) -> 0.67082039 | P6: =IF(K6="","",COUNTA(Data_Items!A4:A1004)) -> 10 | Q6: =IF(K6="","",CONFIDENCE(0.05, O6, P6)) -> 0.41577115 | R6: =IF(K6="","",M6-Q6) -> 2.0842289 | S6: =IF(K6="","",M6+Q6) -> 2.9157711
A7: =IF(Data_Items!E3="Choose Scale","",Data_Items!E3) -> Trustworthiness of Content | B7: =IF(Data_Items!E3="Choose Scale","",AVERAGE(Data_Items!E4:H1004)-4) -> 0.15 | C7: =IF(Data_Items!E3="Choose Scale","",VAR(Data_Items!E4:H1004)) -> 3.1051282 | D7: =IF(Data_Items!E3="Choose Scale","",_xlfn.STDEV.P(Data_Items!E4:H1004)) -> 1.7399713 | E7: =IF(A7="","",MAX(P6:P45)) -> 10 | F7: =IF(A7="","",CONFIDENCE(0.05, D7, E7)) -> 1.0784255 | G7: =IF(A7="","",B7-F7) -> -0.92842555 | H7: =IF(A7="","",B7+F7) -> 1.2284255 | K7: =IF(A6="","",VLOOKUP(A6,Texts!A2:I31,4,FALSE)) -> illogical | L7: =IF(A6="","",VLOOKUP(A6,Texts!A1:I30,5,FALSE)) -> logical | M7: =IF(K7="","",AVERAGE(Data_Items!B4:B1004)-4) -> 2.3 | N7: =IF(K7="","",VAR(Data_Items!B4:B1004)) -> 0.9 | O7: =IF(K7="","",_xlfn.STDEV.P(Data_Items!B4:B1004)) -> 0.9 | P7: =IF(K7="","",COUNTA(Data_Items!B4:B1004)) -> 10 | Q7: =IF(K7="","",CONFIDENCE(0.05, O7, P7)) -> 0.55781553 | R7: =IF(K7="","",M7-Q7) -> 1.7421845 | S7: =IF(K7="","",M7+Q7) -> 2.8578155
A8: =IF(Data_Items!I3="Choose Scale","",Data_Items!I3) -> Response Behavior | B8: =IF(Data_Items!I3="Choose Scale","",AVERAGE(Data_Items!I4:L1004)-4) -> 0.65 | C8: =IF(Data_Items!I3="Choose Scale","",VAR(Data_Items!I4:L1004)) -> 3.1564103 | D8: =IF(Data_Items!I3="Choose Scale","",_xlfn.STDEV.P(Data_Items!I4:L1004)) -> 1.7542805 | E8: =IF(A8="","",MAX(P6:P45)) -> 10 | F8: =IF(A8="","",CONFIDENCE(0.05, D8, E8)) -> 1.0872943 | G8: =IF(A8="","",B8-F8) -> -0.43729433 | H8: =IF(A8="","",B8+F8) -> 1.7372943 | K8: =IF(A6="","",VLOOKUP(A6,Texts!A3:I32,6,FALSE)) -> not plausible | L8: =IF(A6="","",VLOOKUP(A6,Texts!A1:I30,7,FALSE)) -> plausible | M8: =IF(K8="","",AVERAGE(Data_Items!C4:C1004)-4) -> 2.4 | N8: =IF(K8="","",VAR(Data_Items!C4:C1004)) -> 0.71111111 | O8: =IF(K8="","",_xlfn.STDEV.P(Data_Items!C4:C1004)) -> 0.8 | P8: =IF(K8="","",COUNTA(Data_Items!C4:C1004)) -> 10 | Q8: =IF(K8="","",CONFIDENCE(0.05, O8, P8)) -> 0.49583603 | R8: =IF(K8="","",M8-Q8) -> 1.904164 | S8: =IF(K8="","",M8+Q8) -> 2.895836
A9: =IF(Data_Items!M3="Choose Scale","",Data_Items!M3) -> Response Quality | B9: =IF(Data_Items!M3="Choose Scale","",AVERAGE(Data_Items!M3:P1004)-4) -> 0.075 | C9: =IF(Data_Items!M3="Choose Scale","",VAR(Data_Items!M3:P1004)) -> 3.5070513 | D9: =IF(Data_Items!M3="Choose Scale","",_xlfn.STDEV.P(Data_Items!M3:P1004)) -> 1.8491552 | E9: =IF(A9="","",MAX(P6:P45)) -> 10 | F9: =IF(A9="","",CONFIDENCE(0.05, D9, E9)) -> 1.1460972 | G9: =IF(A9="","",B9-F9) -> -1.0710972 | H9: =IF(A9="","",B9+F9) -> 1.2210972 | K9: =IF(A6="","",VLOOKUP(A6,Texts!A3:I33,8,FALSE)) -> inconclusive | L9: =IF(A6="","",VLOOKUP(A6,Texts!A1:I30,9,FALSE)) -> conclusive | M9: =IF(K9="","",AVERAGE(Data_Items!D4:D1004)-4) -> 2.3 | N9: =IF(K9="","",VAR(Data_Items!D4:D1004)) -> 1.1222222 | O9: =IF(K9="","",_xlfn.STDEV.P(Data_Items!D4:D1004)) -> 1.0049876 | P9: =IF(K9="","",COUNTA(Data_Items!D4:D1004)) -> 10 | Q9: =IF(K9="","",CONFIDENCE(0.05, O9, P9)) -> 0.6228863 | R9: =IF(K9="","",M9-Q9) -> 1.6771137 | S9: =IF(K9="","",M9+Q9) -> 2.9228863
A10: =IF(Data_Items!Q3="Choose Scale","",Data_Items!Q3) -> Clarity | B10: =IF(Data_Items!Q3="Choose Scale","",AVERAGE(Data_Items!Q3:T1004)-4) -> 2.475 | C10: =IF(Data_Items!Q3="Choose Scale","",VAR(Data_Items!Q3:T1004)) -> 0.51217949 | D10: =IF(Data_Items!Q3="Choose Scale","",_xlfn.STDEV.P(Data_Items!Q3:T1004)) -> 0.7066647 | E10: =IF(A10="","",MAX(P6:P45)) -> 10 | F10: =IF(A10="","",CONFIDENCE(0.05, D10, E10)) -> 0.43798727 | G10: =IF(A10="","",B10-F10) -> 2.0370127 | H10: =IF(A10="","",B10+F10) -> 2.9129873 | J10: =A7 -> Trustworthiness of Content | K10: =IF(A7="","",VLOOKUP(A7,Texts!A1:I30,2,FALSE)) -> useless | L10: =IF(A7="","",VLOOKUP(A7,Texts!A1:I30,3,FALSE)) -> useful | M10: =IF(K10="","",AVERAGE(Data_Items!E4:E1004)-4) -> 0.3 | N10: =IF(K10="","",VAR(Data_Items!E4:E1004)) -> 3.3444444 | O10: =IF(K10="","",_xlfn.STDEV.P(Data_Items!E4:E1004)) -> 1.7349352 | P10: =IF(K10="","",COUNTA(Data_Items!E4:E1004)) -> 10 | Q10: =IF(K10="","",CONFIDENCE(0.05, O10, P10)) -> 1.0753042 | R10: =IF(K10="","",M10-Q10) -> -0.77530419 | S10: =IF(K10="","",M10+Q10) -> 1.3753042
A11: =IF(Data_Items!U3="Choose Scale","",Data_Items!U3) -> Risk Handling | B11: =IF(Data_Items!U3="Choose Scale","",AVERAGE(Data_Items!U3:X1004)-4) -> -0.75 | C11: =IF(Data_Items!U3="Choose Scale","",VAR(Data_Items!U3:X1004)) -> 2.4487179 | D11: =IF(Data_Items!U3="Choose Scale","",_xlfn.STDEV.P(Data_Items!U3:X1004)) -> 1.5451537 | E11: =IF(A11="","",MAX(P6:P45)) -> 10 | F11: =IF(A11="","",CONFIDENCE(0.05, D11, E11)) -> 0.9576786 | G11: =IF(A11="","",B11-F11) -> -1.7076786 | H11: =IF(A11="","",B11+F11) -> 0.2076786 | K11: =IF(A7="","",VLOOKUP(A7,Texts!A1:I30,4,FALSE)) -> implausible | L11: =IF(A7="","",VLOOKUP(A7,Texts!A1:I30,5,FALSE)) -> plausible | M11: =IF(K11="","",AVERAGE(Data_Items!F4:F1004)-4) -> 0.3 | N11: =IF(K11="","",VAR(Data_Items!F4:F1004)) -> 4.0111111 | O11: =IF(K11="","",_xlfn.STDEV.P(Data_Items!F4:F1004)) -> 1.9 | P11: =IF(K11="","",COUNTA(Data_Items!F4:F1004)) -> 10 | Q11: =IF(K11="","",CONFIDENCE(0.05, O11, P11)) -> 1.1776106 | R11: =IF(K11="","",M11-Q11) -> -0.87761056 | S11: =IF(K11="","",M11+Q11) -> 1.4776106
A12: =IF(Data_Items!Y3="Choose Scale","",Data_Items!Y3) | B12: =IF(Data_Items!Y3="Choose Scale","",AVERAGE(Data_Items!Y3:AB1004)-4) | C12: =IF(Data_Items!Y3="Choose Scale","",VAR(Data_Items!Y3:AB1004)) | D12: =IF(Data_Items!Y3="Choose Scale","",_xlfn.STDEV.P(Data_Items!Y3:AB1004)) | E12: =IF(A12="","",MAX(P6:P45)) | F12: =IF(A12="","",CONFIDENCE(0.05, D12, E12)) | G12: =IF(A12="","",B12-F12) | H12: =IF(A12="","",B12+F12) | K12: =IF(A7="","",VLOOKUP(A7,Texts!A1:I30,6,FALSE)) -> untrustworthy | L12: =IF(A7="","",VLOOKUP(A7,Texts!A1:I30,7,FALSE)) -> trustworthy | M12: =IF(K12="","",AVERAGE(Data_Items!G4:G1004)-4) -> 0 | N12: =IF(K12="","",VAR(Data_Items!G4:G1004)) -> 2.8888889 | O12: =IF(K12="","",_xlfn.STDEV.P(Data_Items!G4:G1004)) -> 1.6124515 | P12: =IF(K12="","",COUNTA(Data_Items!G4:G1004)) -> 10 | Q12: =IF(K12="","",CONFIDENCE(0.05, O12, P12)) -> 0.99938946 | R12: =IF(K12="","",M12-Q12) -> -0.99938946 | S12: =IF(K12="","",M12+Q12) -> 0.99938946
A13: =IF(Data_Items!AC3="Choose Scale","",Data_Items!AC3) | B13: =IF(Data_Items!AC3="Choose Scale","",AVERAGE(Data_Items!AC3:AF1004)-4) | C13: =IF(Data_Items!AC3="Choose Scale","",VAR(Data_Items!AC3:AF1004)) | D13: =IF(Data_Items!AC3="Choose Scale","",_xlfn.STDEV.P(Data_Items!AC3:AF1004)) | E13: =IF(A13="","",MAX(P6:P45)) | F13: =IF(A13="","",CONFIDENCE(0.05, D13, E13)) | G13: =IF(A13="","",B13-F13) | H13: =IF(A13="","",B13+F13) | K13: =IF(A7="","",VLOOKUP(A7,Texts!A1:I30,8,FALSE)) -> inaccurate | L13: =IF(A7="","",VLOOKUP(A7,Texts!A1:I30,9,FALSE)) -> accurate | M13: =IF(K13="","",AVERAGE(Data_Items!H4:H1004)-4) -> 0 | N13: =IF(K13="","",VAR(Data_Items!H4:H1004)) -> 3.1111111 | O13: =IF(K13="","",_xlfn.STDEV.P(Data_Items!H4:H1004)) -> 1.6733201 | P13: =IF(K13="","",COUNTA(Data_Items!H4:H1004)) -> 10 | Q13: =IF(K13="","",CONFIDENCE(0.05, O13, P13)) -> 1.0371155 | R13: =IF(K13="","",M13-Q13) -> -1.0371155 | S13: =IF(K13="","",M13+Q13) -> 1.0371155
A14: =IF(Data_Items!AG3="Choose Scale","",Data_Items!AG3) | B14: =IF(Data_Items!AG3="Choose Scale","",AVERAGE(Data_Items!AG3:AJ1004)-4) | C14: =IF(Data_Items!AG3="Choose Scale","",VAR(Data_Items!AG3:AJ1004)) | D14: =IF(Data_Items!AG3="Choose Scale","",_xlfn.STDEV.P(Data_Items!AG3:AJ1004)) | E14: =IF(A14="","",MAX(P6:P45)) | F14: =IF(A14="","",CONFIDENCE(0.05, D14, E14)) | G14: =IF(A14="","",B14-F14) | H14: =IF(A14="","",B14+F14) | J14: =A8 -> Response Behavior | K14: =IF(A8="","",VLOOKUP(A8,Texts!A1:I30,2,FALSE)) -> artificial | L14: =IF(A8="","",VLOOKUP(A8,Texts!A1:I30,3,FALSE)) -> natural | M14: =IF(K14="","",AVERAGE(Data_Items!I4:I1004)-4) -> 0.6 | N14: =IF(K14="","",VAR(Data_Items!I4:I1004)) -> 3.8222222 | O14: =IF(K14="","",_xlfn.STDEV.P(Data_Items!I4:I1004)) -> 1.8547237 | P14: =IF(K14="","",COUNTA(Data_Items!I4:I1004)) -> 10 | Q14: =IF(K14="","",CONFIDENCE(0.05, O14, P14)) -> 1.1495485 | R14: =IF(K14="","",M14-Q14) -> -0.54954853 | S14: =IF(K14="","",M14+Q14) -> 1.7495485
A15: =IF(Data_Items!AK3="Choose Scale","",Data_Items!AK3) | B15: =IF(Data_Items!AK3="Choose Scale","",AVERAGE(Data_Items!AK3:AN1004)-4) | C15: =IF(Data_Items!AK3="Choose Scale","",VAR(Data_Items!AK3:AN1004)) | D15: =IF(Data_Items!AK3="Choose Scale","",_xlfn.STDEV.P(Data_Items!AK3:AN1004)) | E15: =IF(A15="","",MAX(P6:P45)) | F15: =IF(A15="","",CONFIDENCE(0.05, D15, E15)) | G15: =IF(A15="","",B15-F15) | H15: =IF(A15="","",B15+F15) | K15: =IF(A8="","",VLOOKUP(A8,Texts!A1:I30,4,FALSE)) -> unpleasant | L15: =IF(A8="","",VLOOKUP(A8,Texts!A1:I30,5,FALSE)) -> pleasant | M15: =IF(K15="","",AVERAGE(Data_Items!J4:J1004)-4) -> 1 | N15: =IF(K15="","",VAR(Data_Items!J4:J1004)) -> 3.7777778 | O15: =IF(K15="","",_xlfn.STDEV.P(Data_Items!J4:J1004)) -> 1.8439089 | P15: =IF(K15="","",COUNTA(Data_Items!J4:J1004)) -> 10 | Q15: =IF(K15="","",CONFIDENCE(0.05, O15, P15)) -> 1.1428456 | R15: =IF(K15="","",M15-Q15) -> -0.14284557 | S15: =IF(K15="","",M15+Q15) -> 2.1428456
K16: =IF(A8="","",VLOOKUP(A8,Texts!A1:I30,6,FALSE)) -> unlikeable | L16: =IF(A8="","",VLOOKUP(A8,Texts!A1:I30,7,FALSE)) -> likeable | M16: =IF(K16="","",AVERAGE(Data_Items!K4:K1004)-4) -> 0.5 | N16: =IF(K16="","",VAR(Data_Items!K4:K1004)) -> 3.1666667 | O16: =IF(K16="","",_xlfn.STDEV.P(Data_Items!K4:K1004)) -> 1.6881943 | P16: =IF(K16="","",COUNTA(Data_Items!K4:K1004)) -> 10 | Q16: =IF(K16="","",CONFIDENCE(0.05, O16, P16)) -> 1.0463344 | R16: =IF(K16="","",M16-Q16) -> -0.54633444 | S16: =IF(K16="","",M16+Q16) -> 1.5463344
K17: =IF(A8="","",VLOOKUP(A8,Texts!A1:I30,8,FALSE)) -> boring | L17: =IF(A8="","",VLOOKUP(A8,Texts!A1:I30,9,FALSE)) -> entertaining | M17: =IF(K17="","",AVERAGE(Data_Items!L4:L1004)-4) -> 0.5 | N17: =IF(K17="","",VAR(Data_Items!L4:L1004)) -> 2.7222222 | O17: =IF(K17="","",_xlfn.STDEV.P(Data_Items!L4:L1004)) -> 1.5652476 | P17: =IF(K17="","",COUNTA(Data_Items!L4:L1004)) -> 10 | Q17: =IF(K17="","",CONFIDENCE(0.05, O17, P17)) -> 0.97013268 | R17: =IF(K17="","",M17-Q17) -> -0.47013268 | S17: =IF(K17="","",M17+Q17) -> 1.4701327
A18: Mean Importance Ratings (see Data_Importance) | J18: =A9 -> Response Quality | K18: =IF(A9="","",VLOOKUP(A9,Texts!A1:I30,2,FALSE)) -> inappropriate | L18: =IF(A9="","",VLOOKUP(A9,Texts!A1:I30,3,FALSE)) -> suitable | M18: =IF(K18="","",AVERAGE(Data_Items!M4:M1004)-4) -> 0.2 | N18: =IF(K18="","",VAR(Data_Items!M4:M1004)) -> 4.1777778 | O18: =IF(K18="","",_xlfn.STDEV.P(Data_Items!M4:M1004)) -> 1.9390719 | P18: =IF(K18="","",COUNTA(Data_Items!M4:M1004)) -> 10 | Q18: =IF(K18="","",CONFIDENCE(0.05, O18, P18)) -> 1.2018272 | R18: =IF(K18="","",M18-Q18) -> -1.0018272 | S18: =IF(K18="","",M18+Q18) -> 1.4018272
A19: Scale | B19: Mean | C19: Variance | D19: Std.dev. | E19: N | F19: Confidence | G19: Confidence Interval | K19: =IF(A9="","",VLOOKUP(A9,Texts!A1:I30,4,FALSE)) -> useless | L19: =IF(A9="","",VLOOKUP(A9,Texts!A1:I30,5,FALSE)) -> useful | M19: =IF(K19="","",AVERAGE(Data_Items!N4:N1004)-4) -> 0 | N19: =IF(K19="","",VAR(Data_Items!N4:N1004)) -> 4.2222222 | O19: =IF(K19="","",_xlfn.STDEV.P(Data_Items!N4:N1004)) -> 1.9493589 | P19: =IF(K19="","",COUNTA(Data_Items!N4:N1004)) -> 10 | Q19: =IF(K19="","",CONFIDENCE(0.05, O19, P19)) -> 1.2082029 | R19: =IF(K19="","",M19-Q19) -> -1.2082029 | S19: =IF(K19="","",M19+Q19) -> 1.2082029
A20: =IF(Data_Items!A3="Choose Scale","",Data_Items!A3) -> Intuitive Use | B20: =IF(Data_Items!A3="Choose Scale","",AVERAGE(Data_Importance!A4:A1004)-4) -> 1.516129 | C20: =IF(Data_Items!A3="Choose Scale","",VAR(Data_Importance!A4:A1004)) -> 0.79139785 | D20: =IF(Data_Items!A3="Choose Scale","",_xlfn.STDEV.P(Data_Importance!A4:A1004)) -> 0.87513935 | E20: =IF(A20="","",COUNTA(Data_Importance!A4:A1004)) -> 31 | F20: =IF(A20="","",CONFIDENCE(0.05, D20, E20)) -> 0.30806649 | G20: =IF(A20="","",B20-F20) -> 1.2080625 | H20: =IF(A20="","",B20+F20) -> 1.8241955 | K20: =IF(A9="","",VLOOKUP(A9,Texts!A1:I30,6,FALSE)) -> not helpful | L20: =IF(A9="","",VLOOKUP(A9,Texts!A1:I30,7,FALSE)) -> helpful | M20: =IF(K20="","",AVERAGE(Data_Items!O4:O1004)-4) -> 0 | N20: =IF(K20="","",VAR(Data_Items!O4:O1004)) -> 2.4444444 | O20: =IF(K20="","",_xlfn.STDEV.P(Data_Items!O4:O1004)) -> 1.4832397 | P20: =IF(K20="","",COUNTA(Data_Items!O4:O1004)) -> 10 | Q20: =IF(K20="","",CONFIDENCE(0.05, O20, P20)) -> 0.9193046 | R20: =IF(K20="","",M20-Q20) -> -0.9193046 | S20: =IF(K20="","",M20+Q20) -> 0.9193046
A21: =IF(Data_Items!E3="Choose Scale","",Data_Items!E3) -> Trustworthiness of Content | B21: =IF(Data_Items!E3="Choose Scale","",AVERAGE(Data_Importance!B4:B1014)-4) -> 2.2333333 | C21: =IF(Data_Items!E3="Choose Scale","",VAR(Data_Importance!B4:B1004)) -> 0.73678161 | D21: =IF(Data_Items!E3="Choose Scale","",_xlfn.STDEV.P(Data_Importance!B4:B1004)) -> 0.84393259 | E21: =IF(A21="","",COUNTA(Data_Importance!B4:B1004)) -> 30 | F21: =IF(A21="","",CONFIDENCE(0.05, D21, E21)) -> 0.30199185 | G21: =IF(A21="","",B21-F21) -> 1.9313415 | H21: =IF(A21="","",B21+F21) -> 2.5353252 | K21: =IF(A9="","",VLOOKUP(A9,Texts!A1:I30,8,FALSE)) -> unintelligent | L21: =IF(A9="","",VLOOKUP(A9,Texts!A1:I30,9,FALSE)) -> intelligent | M21: =IF(K21="","",AVERAGE(Data_Items!P4:P1004)-4) -> 0.1 | N21: =IF(K21="","",VAR(Data_Items!P4:P1004)) -> 4.3222222 | O21: =IF(K21="","",_xlfn.STDEV.P(Data_Items!P4:P1004)) -> 1.9723083 | P21: =IF(K21="","",COUNTA(Data_Items!P4:P1004)) -> 10 | Q21: =IF(K21="","",CONFIDENCE(0.05, O21, P21)) -> 1.2224269 | R21: =IF(K21="","",M21-Q21) -> -1.1224269 | S21: =IF(K21="","",M21+Q21) -> 1.3224269
A22: =IF(Data_Items!I3="Choose Scale","",Data_Items!I3) -> Response Behavior | B22: =IF(Data_Items!I3="Choose Scale","",AVERAGE(Data_Importance!C4:C1004)-4) -> 1.8064516 | C22: =IF(Data_Items!I3="Choose Scale","",VAR(Data_Importance!C4:C1004)) -> 1.227957 | D22: =IF(Data_Items!I3="Choose Scale","",_xlfn.STDEV.P(Data_Importance!C4:C1004)) -> 1.0901126 | E22: =IF(A22="","",COUNTA(Data_Importance!C4:C1004)) -> 31 | F22: =IF(A22="","",CONFIDENCE(0.05, D22, E22)) -> 0.38374135 | G22: =IF(A22="","",B22-F22) -> 1.4227103 | H22: =IF(A22="","",B22+F22) -> 2.190193 | J22: =A10 -> Clarity | K22: =IF(A10="","",VLOOKUP(A10,Texts!A1:I30,2,FALSE)) -> poorly grouped | L22: =IF(A10="","",VLOOKUP(A10,Texts!A1:I30,3,FALSE)) -> well grouped | M22: =IF(K22="","",AVERAGE(Data_Items!Q4:Q1004)-4) -> 2.5 | N22: =IF(K22="","",VAR(Data_Items!Q4:Q1004)) -> 0.5 | O22: =IF(K22="","",_xlfn.STDEV.P(Data_Items!Q4:Q1004)) -> 0.67082039 | P22: =IF(K22="","",COUNTA(Data_Items!Q4:Q1004)) -> 10 | Q22: =IF(K22="","",CONFIDENCE(0.05, O22, P22)) -> 0.41577115 | R22: =IF(K22="","",M22-Q22) -> 2.0842289 | S22: =IF(K22="","",M22+Q22) -> 2.9157711
A23: =IF(Data_Items!M3="Choose Scale","",Data_Items!M3) -> Response Quality | B23: =IF(Data_Items!M3="Choose Scale","",AVERAGE(Data_Importance!D4:D1004)-4) -> 1.0666667 | C23: =IF(Data_Items!M3="Choose Scale","",VAR(Data_Importance!D4:D1004)) -> 1.9264368 | D23: =IF(Data_Items!M3="Choose Scale","",_xlfn.STDEV.P(Data_Importance!D4:D1004)) -> 1.3646326 | E23: =IF(A23="","",COUNTA(Data_Importance!D4:D1004)) -> 30 | F23: =IF(A23="","",CONFIDENCE(0.05, D23, E23)) -> 0.48831854 | G23: =IF(A23="","",B23-F23) -> 0.57834812 | H23: =IF(A23="","",B23+F23) -> 1.5549852 | K23: =IF(A10="","",VLOOKUP(A10,Texts!A1:I30,4,FALSE)) -> unstructured | L23: =IF(A10="","",VLOOKUP(A10,Texts!A1:I30,5,FALSE)) -> structured | M23: =IF(K23="","",AVERAGE(Data_Items!R4:R1004)-4) -> 2.4 | N23: =IF(K23="","",VAR(Data_Items!R4:R1004)) -> 0.71111111 | O23: =IF(K23="","",_xlfn.STDEV.P(Data_Items!R4:R1004)) -> 0.8 | P23: =IF(K23="","",COUNTA(Data_Items!R4:R1004)) -> 10 | Q23: =IF(K23="","",CONFIDENCE(0.05, O23, P23)) -> 0.49583603 | R23: =IF(K23="","",M23-Q23) -> 1.904164 | S23: =IF(K23="","",M23+Q23) -> 2.895836
A24: =IF(Data_Items!Q3="Choose Scale","",Data_Items!Q3) -> Clarity | B24: =IF(Data_Items!Q3="Choose Scale","",AVERAGE(Data_Importance!E3:E1004)-4) -> 1.5483871 | C24: =IF(Data_Items!Q3="Choose Scale","",VAR(Data_Importance!E4:E1004)) -> 1.1892473 | D24: =IF(Data_Items!Q3="Choose Scale","",_xlfn.STDEV.P(Data_Importance!E4:E1004)) -> 1.0727928 | E24: =IF(A24="","",COUNTA(Data_Importance!E4:E1004)) -> 31 | F24: =IF(A24="","",CONFIDENCE(0.05, D24, E24)) -> 0.37764446 | G24: =IF(A24="","",B24-F24) -> 1.1707426 | H24: =IF(A24="","",B24+F24) -> 1.9260316 | K24: =IF(A10="","",VLOOKUP(A10,Texts!A1:I30,6,FALSE)) -> disordered | L24: =IF(A10="","",VLOOKUP(A10,Texts!A1:I30,7,FALSE)) -> ordered | M24: =IF(K24="","",AVERAGE(Data_Items!S4:S1004)-4) -> 2.5 | N24: =IF(K24="","",VAR(Data_Items!S4:S1004)) -> 0.5 | O24: =IF(K24="","",_xlfn.STDEV.P(Data_Items!S4:S1004)) -> 0.67082039 | P24: =IF(K24="","",COUNTA(Data_Items!S4:S1004)) -> 10 | Q24: =IF(K24="","",CONFIDENCE(0.05, O24, P24)) -> 0.41577115 | R24: =IF(K24="","",M24-Q24) -> 2.0842289 | S24: =IF(K24="","",M24+Q24) -> 2.9157711
A25: =IF(Data_Items!U3="Choose Scale","",Data_Items!U3) -> Risk Handling | B25: =IF(Data_Items!U3="Choose Scale","",AVERAGE(Data_Importance!F4:F1004)-4) -> 1.5806452 | C25: =IF(Data_Items!U3="Choose Scale","",VAR(Data_Importance!F4:F1004)) -> 1.0516129 | D25: =IF(Data_Items!U3="Choose Scale","",_xlfn.STDEV.P(Data_Importance!F4:F1004)) -> 1.0088062 | E25: =IF(A25="","",COUNTA(Data_Importance!F4:F1004)) -> 31 | F25: =IF(A25="","",CONFIDENCE(0.05, D25, E25)) -> 0.35511987 | G25: =IF(A25="","",B25-F25) -> 1.2255253 | H25: =IF(A25="","",B25+F25) -> 1.935765 | K25: =IF(A10="","",VLOOKUP(A10,Texts!A1:I30,8,FALSE)) -> disorganized | L25: =IF(A10="","",VLOOKUP(A10,Texts!A1:I30,9,FALSE)) -> organized | M25: =IF(K25="","",AVERAGE(Data_Items!T4:T1004)-4) -> 2.5 | N25: =IF(K25="","",VAR(Data_Items!T4:T1004)) -> 0.5 | O25: =IF(K25="","",_xlfn.STDEV.P(Data_Items!T4:T1004)) -> 0.67082039 | P25: =IF(K25="","",COUNTA(Data_Items!T4:T1004)) -> 10 | Q25: =IF(K25="","",CONFIDENCE(0.05, O25, P25)) -> 0.41577115 | R25: =IF(K25="","",M25-Q25) -> 2.0842289 | S25: =IF(K25="","",M25+Q25) -> 2.9157711
A26: =IF(Data_Items!Y3="Choose Scale","",Data_Items!Y3) | B26: =IF(Data_Items!Y3="Choose Scale","",AVERAGE(Data_Importance!G4:G1004)-4) | C26: =IF(Data_Items!Y3="Choose Scale","",VAR(Data_Importance!G4:G1004)) | D26: =IF(Data_Items!Y3="Choose Scale","",_xlfn.STDEV.P(Data_Importance!G4:G1004)) | E26: =IF(A26="","",COUNTA(Data_Importance!G4:G1004)) | F26: =IF(A26="","",CONFIDENCE(0.05, D26, E26)) | G26: =IF(A26="","",B26-F26) | H26: =IF(A26="","",B26+F26) | J26: =A11 -> Risk Handling | K26: =IF(A11="","",VLOOKUP(A11,Texts!A1:I30,2,FALSE)) -> hardly apparent | L26: =IF(A11="","",VLOOKUP(A11,Texts!A1:I30,3,FALSE)) -> easily apparent | M26: =IF(K26="","",AVERAGE(Data_Items!U4:U1004)-4) -> -1 | N26: =IF(K26="","",VAR(Data_Items!U4:U1004)) -> 2 | O26: =IF(K26="","",_xlfn.STDEV.P(Data_Items!U4:U1004)) -> 1.3416408 | P26: =IF(K26="","",COUNTA(Data_Items!U4:U1004)) -> 10 | Q26: =IF(K26="","",CONFIDENCE(0.05, O26, P26)) -> 0.83154229 | R26: =IF(K26="","",M26-Q26) -> -1.8315423 | S26: =IF(K26="","",M26+Q26) -> -0.16845771
A27: =IF(Data_Items!AC3="Choose Scale","",Data_Items!AC3) | B27: =IF(Data_Items!AC3="Choose Scale","",AVERAGE(Data_Importance!H4:H1004)-4) | C27: =IF(Data_Items!AC3="Choose Scale","",VAR(Data_Importance!H4:H1004)) | D27: =IF(Data_Items!AC3="Choose Scale","",_xlfn.STDEV.P(Data_Importance!H4:H1004)) | E27: =IF(A27="","",COUNTA(Data_Importance!H4:H1004)) | F27: =IF(A27="","",CONFIDENCE(0.05, D27, E27)) | G27: =IF(A27="","",B27-F27) | H27: =IF(A27="","",B27+F27) | K27: =IF(A11="","",VLOOKUP(A11,Texts!A1:I30,4,FALSE)) -> not fed back in a timely manner | L27: =IF(A11="","",VLOOKUP(A11,Texts!A1:I30,5,FALSE)) -> fed back in a timely manner | M27: =IF(K27="","",AVERAGE(Data_Items!V4:V1004)-4) -> -1 | N27: =IF(K27="","",VAR(Data_Items!V4:V1004)) -> 2.6666667 | O27: =IF(K27="","",_xlfn.STDEV.P(Data_Items!V4:V1004)) -> 1.5491933 | P27: =IF(K27="","",COUNTA(Data_Items!V4:V1004)) -> 10 | Q27: =IF(K27="","",CONFIDENCE(0.05, O27, P27)) -> 0.96018234 | R27: =IF(K27="","",M27-Q27) -> -1.9601823 | S27: =IF(K27="","",M27+Q27) -> -0.039817665
